[32mINFO    [0m root:test_001_login.py:83 **** Starting test_login_data_driven for invalid_user ****
[32mINFO    [0m root:test_001_login.py:104 Expecting FAIL
[1m[31mERROR   [0m root:test_001_login.py:110 **** Test FAILED for invalid_user (Expected: Fail, but no error found) ****