[32mINFO    [0m root:test_001_login.py:83 **** Starting test_login_data_driven for invalid_user ****
[32mINFO    [0m root:test_001_login.py:104 Expecting FAIL
[32mINFO    [0m root:test_001_login.py:108 **** Test PASSED for invalid_user (Expected: Fail, error message shown) ****